<?xml version="1.0"?>
<robot name="autonomous_robot" xmlns:xacro="http://ros.org/wiki/xacro">

<!-- robot specifications to be reused throughout the URDF -->
  <!-- robot base dimensions -->
  <xacro:property name="base_width" value="0.31"/>
  <xacro:property name="base_length" value="0.42"/>
  <xacro:property name="base_height" value="0.18"/>

  <!-- robot wheels dimensions -->
  <xacro:property name="wheel_radius" value="0.10"/>
  <xacro:property name="wheel_width" value="0.16"/>
  
  <!-- adjusts the gap between the wheel and the chassis along the y-axis -->
  <xacro:property name="wheel_ygap" value="0.025"/>
  
  <!-- position the back wheels along the z-axis and x-axis appropriately --> 
  <xacro:property name="wheel_back_zoff" value="0.05"/>
  <xacro:property name="wheel_back_xoff" value="0.30"/>
  
  <!-- position the front wheels along the z-axis and x-axis appropriately --> 
  <xacro:property name="wheel_front_zoff" value="0.05"/>
  <xacro:property name="wheel_front_xoff" value="-0.08"/>
  
  <!-- cylinder radius -->
  <xacro:property name="cylinder_radius" value="0.025"/>
  
<!-- Define intertial property macros  -->
  <xacro:macro name="box_inertia" params="m w h d">
    <inertial>
      <origin xyz="0 0 0" rpy="${pi/2} 0 ${pi/2}"/>
      <mass value="${m}"/>
      <inertia ixx="${(m/12) * (h*h + d*d)}" ixy="0.0" ixz="0.0" iyy="${(m/12) * (w*w + d*d)}" iyz="0.0" izz="${(m/12) * (w*w + h*h)}"/>
    </inertial>
  </xacro:macro>

  <xacro:macro name="cylinder_inertia" params="m r h">
    <inertial>
      <origin xyz="0 1 1" rpy="${pi/2} 0 0" />
      <mass value="${m}"/>
      <inertia ixx="${(m/12) * (3*r*r + h*h)}" ixy = "0" ixz = "0" iyy="${(m/12) * (3*r*r + h*h)}" iyz = "0" izz="${(m/2) * (r*r)}"/>
    </inertial>
  </xacro:macro>

  <xacro:macro name="sphere_inertia" params="m r">
    <inertial>
      <mass value="${m}"/>
      <inertia ixx="${(2/5) * m * (r*r)}" ixy="0.0" ixz="0.0" iyy="${(2/5) * m * (r*r)}" iyz="0.0" izz="${(2/5) * m * (r*r)}"/>
    </inertial>
  </xacro:macro>
  
<!-- robot base visual -->
  <link name="base_link">
    <visual>
      <geometry>
        <box size="${base_length} ${base_width} ${base_height}"/>
      </geometry>
      <material name="Cyan">
        <color rgba="0 1.0 1.0 1.0"/>
      </material>
    </visual>
    
<!-- collision data - base -->
    <collision>
      <geometry>
        <box size="${base_length} ${base_width} ${base_height}"/>
      </geometry>
    </collision>

    <xacro:box_inertia m="15" w="${base_width}" d="${base_length}" h="${base_height}"/>
  </link>
  

<!-- robot footprint used to determine the center of the robot porjected to the ground -->
  <link name="base_footprint"/>

  <joint name="base_joint" type="fixed">
    <parent link="base_link"/>
    <child link="base_footprint"/>
    <origin xyz="0.0 0.0 ${-(wheel_radius+wheel_back_zoff)}" rpy="0 0 0"/>
  </joint>
  
  
<!-- robot counter weight visual -->
  <link name="base_counterweight_link">
    <visual>
      <origin xyz="0 0 0" rpy="0 0 0"/>
      <geometry>
        <box size="${base_length/2} ${base_width} ${base_height*2}"/>
      </geometry>
      <material name="Cyan">
        <color rgba="0 1.0 1.0 1.0"/>
      </material>
    </visual>
    
    <!-- collision data - counter weight-->
    <collision>
      <geometry>
        <box size="${base_length/2} ${base_width} ${base_height*2}"/>
      </geometry>
    </collision>

    <xacro:box_inertia m="15" w="${base_width}" d="${base_length/2}" h="${base_height*2}"/>    
  </link> 
  
  <joint name="counter_weight_joint" type="fixed">
    <parent link="base_link"/>
    <child link="base_counterweight_link"/>
    <origin xyz="-0.315 0.0 0.090" rpy="0 0 0"/>
  </joint>
    
<!-- wheels back -->
  <xacro:macro name="wheel" params="prefix x_reflect y_reflect">
    <link name="${prefix}_link">
      <visual>
        <origin xyz="0 0 0" rpy="${pi/2} 0 0"/>
        <geometry>
            <cylinder radius="${wheel_radius}" length="${wheel_width}"/>
        </geometry>
        <material name="Gray">
          <color rgba="0.5 0.5 0.5 1.0"/>
        </material>
      </visual>
      
<!-- collision data - wheel -->  
     <collision>
        <origin xyz="0 0 0" rpy="${pi/2} 0 0"/>
        <geometry>
          <cylinder radius="${wheel_radius}" length="${wheel_width}"/>
        </geometry>
      </collision>

      <xacro:cylinder_inertia m="0.5" r="${wheel_radius}" h="${wheel_width}"/>  
    </link>

    <joint name="${prefix}_joint" type="continuous">
      <parent link="base_link"/>
      <child link="${prefix}_link"/>
      <origin xyz="${x_reflect*wheel_back_xoff} ${y_reflect*(base_width/2+wheel_ygap)} ${-wheel_back_zoff}" rpy="0 0 0"/>
      <axis xyz="0 1 0"/>
    </joint>
  </xacro:macro>

  <xacro:wheel prefix="drivewhl_l_back" x_reflect="-1" y_reflect="1" />
  <xacro:wheel prefix="drivewhl_r_back" x_reflect="-1" y_reflect="-1" />
  
<!-- wheels front -->
  <xacro:macro name="wheel" params="prefix x_reflect y_reflect">
    <link name="${prefix}_link">
      <visual>
        <origin xyz="0 0 0" rpy="${pi/2} 0 0"/>
        <geometry>
            <cylinder radius="${wheel_radius}" length="${wheel_width}"/>
        </geometry>
        <material name="Gray">
          <color rgba="0.5 0.5 0.5 1.0"/>
        </material>
      </visual>
              
     <collision>
        <origin xyz="0 0 0" rpy="${pi/2} 0 0"/>
        <geometry>
          <cylinder radius="${wheel_radius}" length="${wheel_width}"/>
        </geometry>
      </collision>
      
      <xacro:cylinder_inertia m="0.5" r="${wheel_radius}" h="${wheel_width}"/> 
    </link>

    <joint name="${prefix}_joint" type="continuous">
      <parent link="base_link"/>
      <child link="${prefix}_link"/>
      <origin xyz="${x_reflect*wheel_front_xoff} ${y_reflect*(base_width/2+wheel_ygap)} ${-wheel_front_zoff}" rpy="0 0 0"/>
      <axis xyz="0 1 0"/>
    </joint>
  </xacro:macro>

  <xacro:wheel prefix="drivewhl_l_front" x_reflect="-1" y_reflect="1" />
  <xacro:wheel prefix="drivewhl_r_front" x_reflect="-1" y_reflect="-1" />
  
  
<!-- manipulator arm - first joint -->   
    <link name="first_joint">
      <visual>
        <geometry>
          <cylinder length="0.4" radius="${cylinder_radius}"/>
        </geometry>
        <origin rpy="0 1.57075 0 " xyz="-0.20 0 0"/>
      </visual>
    </link>  
    
    <joint name="first_joint_base" type="revolute">
      <axis xyz="0 1 0"/>
      <limit effort="1000.0" lower="-0.7" upper="1.35" velocity="0.5"/>
      <parent link="base_link"/>
      <child link="first_joint"/>
      <origin rpy="0 1.5708 0" xyz="0 0 0.09"/>
    </joint>
  
  
<!-- manipulator arm - first joint enclosure --> 
    <link name="first_joint_enclosure">
      <visual>
        <geometry>
          <box size="${base_length/5} ${base_width/5} ${base_height/2}"/>
        </geometry>
        <origin rpy="0 0 0 " xyz="0 0 0"/>
      </visual>
    </link>
    
    <joint name="first_joint_enclosure_joint" type="fixed">
      <parent link="base_link"/>
      <child link="first_joint_enclosure"/>
      <origin rpy="0 0 0" xyz="0 0 0.13"/>
    </joint> 
    
  
<!-- manipulator arm - second joint --> 
    <link name="second_joint">
      <visual>
        <geometry>
          <cylinder length="0.6" radius="${cylinder_radius}"/>
        </geometry>
        <origin rpy="0 1.5708 0 " xyz="0.278 0 0"/>
      </visual>
    </link>
    
    <joint name="second_joint_base" type="revolute">
      <axis xyz="0 1 0"/>
      <limit effort="1000.0" lower="-1.0" upper="1.0" velocity="0.5"/>
      <parent link="first_joint"/>
      <child link="second_joint"/>
      <origin rpy="0 -1.5708 0" xyz="-0.4 0 0"/>
    </joint>


<!-- manipulator arm - second joint enclosure --> 
    <link name="second_joint_enclosure">
      <visual>
        <geometry>
          <box size="${base_length/5} ${base_width/5} ${base_height/2}"/>
        </geometry>
        <origin rpy="0 0 0 " xyz="0.0 0 0"/>
      </visual>
    </link>
    
    <joint name="second_joint_enclosure_joint" type="fixed">
      <parent link="first_joint"/>
      <child link="second_joint_enclosure"/>
      <origin rpy="0 0 0" xyz="-0.4 0 0"/>
    </joint> 


<!-- manipulator arm - third joint --> 
    <link name="third_joint">
      <visual>
        <geometry>
          <cylinder length="0.2" radius="${cylinder_radius}"/>
        </geometry>
        <origin rpy="0 1.5708 0 " xyz="0.098 0 0"/>
      </visual>
    </link>
    
    <joint name="third_joint_base" type="revolute">
      <axis xyz="0 1 0"/>
      <limit effort="1000.0" lower="-1.35" upper="1.35" velocity="0.5"/>
      <parent link="second_joint"/>
      <child link="third_joint"/>
      <origin rpy="0 0 0" xyz="0.58 0 0"/>
    </joint> 
    

<!-- manipulator arm - third joint enclosure --> 
    <link name="third_joint_enclosure">
      <visual>
        <geometry>
          <box size="${base_length/5} ${base_width/5} ${base_height/2}"/>
        </geometry>
        <origin rpy="0 0 0 " xyz="0.0 0 0"/>
      </visual>
    </link>
    
    <joint name="third_joint_enclosure_joint" type="fixed">
      <parent link="second_joint"/>
      <child link="third_joint_enclosure"/>
      <origin rpy="0 0 0" xyz="0.58 0 0"/>
    </joint> 

    
<!-- manipulator arm - grabber fixture --> 
    <link name="grabber_fixture">
      <visual>
        <geometry>
          <box size="${base_length} ${base_width/5} ${base_height/3}"/>
        </geometry>
        <origin rpy="0 0 1.5708 " xyz="0 0 0"/>
      </visual>
    </link>
    
    <joint name="grabber_fixture_joint" type="fixed">
      <parent link="third_joint"/>
      <child link="grabber_fixture"/>
      <origin rpy="0 0 0" xyz="0.2 0 0"/>
    </joint> 
    

<!-- manipulator arm - grabber fixture left --> 
    <link name="grabber_fixture_left">
      <visual>
        <geometry>
          <cylinder length="0.3" radius="${cylinder_radius}"/>
        </geometry>
        <origin rpy="-1.5708 0 0" xyz="0 0.13 0"/>
      </visual>
    </link>
    
    <joint name="grabber_fixture_left_joint" type="prismatic">
      <axis xyz="0 1 0"/>
      <limit effort="1000.0" lower="0" upper="0.20" velocity="0.5"/>
      <parent link="grabber_fixture"/>
      <child link="grabber_fixture_left"/>
      <origin rpy="0 0 0" xyz="0 0 0"/>
    </joint> 

  
<!-- manipulator arm - grabber fixture right --> 
    <link name="grabber_fixture_right">
      <visual>
        <geometry>
          <cylinder length="0.3" radius="${cylinder_radius}"/>
        </geometry>
        <origin rpy="1.5708 0 0" xyz="0 -0.13 0"/>
      </visual>
    </link>
    
    <joint name="grabber_fixture_right_joint" type="prismatic">
      <axis xyz="0 -1 0"/>
      <limit effort="1000.0" lower="0" upper="0.20" velocity="0.5"/>
      <parent link="grabber_fixture"/>
      <child link="grabber_fixture_right"/>
      <origin rpy="0 0 0" xyz="0 0 0"/>
    </joint> 
    
    
<!-- manipulator arm - left gripper -->   
    <joint name="left_gripper_joint" type="revolute">
      <axis xyz="0 0 1"/>
      <limit effort="1000.0" lower="-0.548" upper="0.548" velocity="0.5"/>
      <origin rpy="0 0 0" xyz="0.02 0.28 0"/>
      <parent link="grabber_fixture_left"/>
      <child link="left_gripper"/>
    </joint>
  
    <link name="left_gripper">
      <visual>
        <origin rpy="0 0 0" xyz="0 0 0"/>
        <geometry>
          <mesh filename="package://urdf_tutorial/meshes/l_finger.dae"/>
        </geometry>
      </visual>
    </link>
  
    <joint name="left_tip_joint" type="fixed">
      <parent link="left_gripper"/>
      <child link="left_tip"/>
    </joint>
  
    <link name="left_tip">
      <visual>
        <origin rpy="0 0 0" xyz="0.09137 0.00495 0"/>
        <geometry>
          <mesh filename="package://urdf_tutorial/meshes/l_finger_tip.dae"/>
        </geometry>
      </visual>
    </link>
    
    
<!-- manipulator arm - right gripper -->  
    <joint name="right_gripper_joint" type="revolute">
      <axis xyz="0 0 -1"/>
      <limit effort="1000.0" lower="-0.548" upper="0.548" velocity="0.5"/>
      <origin rpy="0 0 0" xyz="0.02 -0.28 0"/>
      <parent link="grabber_fixture_right"/>
      <child link="right_gripper"/>
    </joint>
  
    <link name="right_gripper">
      <visual>
        <origin rpy="-3.1415 0 0" xyz="0 0 0"/>
        <geometry>
          <mesh filename="package://urdf_tutorial/meshes/l_finger.dae"/>
        </geometry>
      </visual>
    </link>
  
    <joint name="right_tip_joint" type="fixed">
      <parent link="right_gripper"/>
      <child link="right_tip"/>
    </joint>
  
    <link name="right_tip">
      <visual>
        <origin rpy="-3.1415 0 0" xyz="0.09137 0.00495 0"/>
        <geometry>
          <mesh filename="package://urdf_tutorial/meshes/l_finger_tip.dae"/>
        </geometry>
      </visual>
    </link>

</robot>
