<?xml version="1.0"?>
<robot name="autonomous_robot" xmlns:xacro="http://ros.org/wiki/xacro">

<!-- robot specifications to be reused throughout the URDF -->
  <!-- colour definitions -->
  <material name="Black">
    <color rgba="0 0 0 1.0"/>
  </material>
  
  <material name="Grey">
   <color rgba="0.5 0.5 0.5 1.0"/>
  </material>
  
  <material name="Cyan">
   <color rgba="0 1.0 1.0 1.0"/>
  </material>
  
  <material name="White">
    <color rgba="1 1 1 1"/>
  </material>
  
<!--################################ SCALING ###################################-->
  <!-- development note: the bigger the number the smaller the number -->
  <!-- default = 1. example: 2 = 50% size, 0.5 = 200% size -->
  <xacro:property name="scale" value="2"/>

<!--############################## DEFINITIONS #################################-->
  <!-- robot base definitions -->
  <xacro:property name="base_width" value="${0.55/scale}"/>
  <xacro:property name="base_length" value="${0.90/scale}"/>
  <xacro:property name="base_height" value="${0.18/scale}"/>

  <!-- robot wheels dimensions -->
  <xacro:property name="wheel_radius" value="${0.10/scale}"/>
  <xacro:property name="wheel_width" value="${0.20/scale}"/>
  
  <!-- adjusts the gap between the wheel and the chassis along the y-axis -->
  <xacro:property name="wheel_ygap" value="${0.10/scale}"/>
  
  <!-- position the back wheels along the z-axis and x-axis appropriately --> 
  <xacro:property name="wheel_back_zoff" value="${0.05/scale}"/>
  <xacro:property name="wheel_back_xoff" value="${0.30/scale}"/>
  
  <!-- position the middle wheels along the z-axis and x-axis appropriately --> 
  <xacro:property name="wheel_middle_zoff" value="${0.05/scale}"/>
  <xacro:property name="wheel_middle_xoff" value="${0/scale}"/>
  
  <!-- position the front wheels along the z-axis and x-axis appropriately --> 
  <xacro:property name="wheel_front_zoff" value="${0.05/scale}"/>
  <xacro:property name="wheel_front_xoff" value="${-0.3/scale}"/>
  
  <!-- cylinder radius -->
  <xacro:property name="cylinder_radius" value="${0.025/scale}"/>
  
  
<!-- Define intertial property macro  -->
  <xacro:macro name="default_inertial" params="mass">
    <inertial>
      <mass value="${mass}" />
      <inertia ixx="1.0" ixy="0.0" ixz="0.0" iyy="1.0" iyz="0.0" izz="1.0" />
    </inertial>
  </xacro:macro>
  
<!--################################# BASE #####################################-->  
<!-- robot base visual -->
  <!-- development note: dummy link as a workaround for warning: -->
  <!-- "The root link base_link has an inertia specified in the URDF, but KDL does not support a root link with an inertia" -->
  <gazebo reference="base_link">
    <material>Gazebo/FlatBlack</material>
  </gazebo>

  <link name="base_link">
    <visual>
      <geometry>
        <box size="${base_length} ${base_width} ${base_height}"/>
      </geometry>
        <material name="Black"/>
    </visual>
      
      
<!-- collision data - base -->
    <collision>
      <geometry>
        <box size="${base_length} ${base_width} ${base_height}"/>
      </geometry>
    </collision>

    <xacro:default_inertial mass="${100/scale}"/>
  </link>

<!--################################ WHEELS ####################################-->      
<!-- wheels back -->
  <xacro:macro name="wheel_back" params="prefix x_reflect y_reflect">
    <gazebo reference="${prefix}_back_link">
 	<mu1 value="1.0"/>
 	<mu2 value="1.0"/>
 	<kp value="10000000.0" />
 	<kd value="1.0" />
 	<fdir1 value="1 0 0"/>
      <material>Gazebo/Cyan</material>
    </gazebo>
    
    <link name="${prefix}_back_link">
      <visual>
        <origin xyz="${0.0/scale} ${0.0/scale} ${0.0/scale}" rpy="${pi/2} 0 0"/>
        <geometry>
            <cylinder radius="${wheel_radius}" length="${wheel_width}"/>
        </geometry>
        <material name="Cyan"/>
      </visual>
      
      
<!-- collision data - wheel back -->  
     <collision>
        <origin xyz="${0.0/scale} ${0.0/scale} ${0.0/scale}" rpy="${pi/2} 0 0"/>
        <geometry>
          <cylinder radius="${wheel_radius}" length="${wheel_width}"/>
        </geometry>
      </collision>

    <xacro:default_inertial mass="${0.5/scale}"/> 
    </link>

    <joint name="${prefix}_back_joint" type="continuous">
      <parent link="base_link"/>
      <child link="${prefix}_back_link"/>
      <origin xyz="${(x_reflect*wheel_back_xoff)} ${y_reflect*(base_width/2+wheel_ygap)} ${-wheel_back_zoff}" rpy="0 0 0"/>
      <axis xyz="0 1 0"/>
    </joint>
    
 <!-- controller - wheels back -->
    <transmission name="${prefix}_back_link_trans">
      <type>transmission_interface/SimpleTransmission</type>
      <actuator name="${prefix}_back_link_motor">
        <mechanicalReduction>1</mechanicalReduction>
      </actuator>
      <joint name="${prefix}_back_joint">
        <hardwareInterface>hardware_interface/VelocityJointInterface</hardwareInterface>
      </joint>
    </transmission>
  
  </xacro:macro>

  <xacro:wheel_back prefix="drivewhl_l" x_reflect="-1" y_reflect="1" />
  <xacro:wheel_back prefix="drivewhl_r" x_reflect="-1" y_reflect="-1" />
  

<!-- wheels middle -->
  <xacro:macro name="wheel_middle" params="prefix x_reflect y_reflect">
    <gazebo reference="${prefix}_middle_link">
 	<mu1 value="1.0"/>
 	<mu2 value="1.0"/>
 	<kp value="10000000.0" />
 	<kd value="1.0" />
 	<fdir1 value="1 0 0"/>
      <material>Gazebo/White</material>
    </gazebo>
    
    <link name="${prefix}_middle_link">
      <visual>
        <origin xyz="${0.0/scale} ${0.0/scale} ${0.0/scale}" rpy="${pi/2} 0 0"/>
        <geometry>
            <cylinder radius="${wheel_radius}" length="${wheel_width}"/>
        </geometry>
        <material name="White"/>
      </visual>
      
<!-- collision data - wheel middle -->               
     <collision>
        <origin xyz="0 0 0" rpy="${pi/2} 0 0"/>
        <geometry>
          <cylinder radius="${wheel_radius}" length="${wheel_width}"/>
        </geometry>
      </collision>
      
    <xacro:default_inertial mass="${0.5/scale}"/>
    </link>

    <joint name="${prefix}_middle_joint" type="continuous">
      <parent link="base_link"/>
      <child link="${prefix}_middle_link"/>
      <origin xyz="${x_reflect*wheel_middle_xoff} ${y_reflect*(base_width/2+wheel_ygap)} ${-wheel_middle_zoff}" rpy="0 0 0"/>
      <axis xyz="0 1 0"/>
    </joint>
    
<!-- controller - wheels middle -->
    <transmission name="${prefix}_middle_link_trans">
      <type>transmission_interface/SimpleTransmission</type>
      <actuator name="${prefix}_middle_link_motor">
        <mechanicalReduction>1</mechanicalReduction>
      </actuator>
      <joint name="${prefix}_middle_joint">
        <hardwareInterface>hardware_interface/VelocityJointInterface</hardwareInterface>
      </joint>
    </transmission>
  
  </xacro:macro>

  <xacro:wheel_middle prefix="drivewhl_l" x_reflect="-1" y_reflect="1" />
  <xacro:wheel_middle prefix="drivewhl_r" x_reflect="-1" y_reflect="-1" />
  

<!-- wheels front -->
  <xacro:macro name="wheel_front" params="prefix x_reflect y_reflect">
    <gazebo reference="${prefix}_front_link">
 	<mu1 value="1.0"/>
 	<mu2 value="1.0"/>
 	<kp value="10000000.0" />
 	<kd value="1.0" />
 	<fdir1 value="1 0 0"/>
      <material>Gazebo/Cyan</material>
    </gazebo>
    
    <link name="${prefix}_front_link">
      <visual>
        <origin xyz="${0.0/scale} ${0.0/scale} ${0.0/scale}" rpy="${pi/2} 0 0"/>
        <geometry>
            <cylinder radius="${wheel_radius}" length="${wheel_width}"/>
        </geometry>
        <material name="Cyan"/>
      </visual>
      
<!-- collision data - wheel front -->               
     <collision>
        <origin xyz="0 0 0" rpy="${pi/2} 0 0"/>
        <geometry>
          <cylinder radius="${wheel_radius}" length="${wheel_width}"/>
        </geometry>
      </collision>
      
    <xacro:default_inertial mass="${0.5/scale}"/>
    </link>

    <joint name="${prefix}_front_joint" type="continuous">
      <parent link="base_link"/>
      <child link="${prefix}_front_link"/>
      <origin xyz="${x_reflect*wheel_front_xoff} ${y_reflect*(base_width/2+wheel_ygap)} ${-wheel_front_zoff}" rpy="0 0 0"/>
      <axis xyz="0 1 0"/>
    </joint>
    
    
<!-- controller - wheels front -->
    <transmission name="${prefix}_front_link_trans">
      <type>transmission_interface/SimpleTransmission</type>
      <actuator name="${prefix}_front_link_motor">
        <mechanicalReduction>1</mechanicalReduction>
      </actuator>
      <joint name="${prefix}_front_joint">
        <hardwareInterface>hardware_interface/VelocityJointInterface</hardwareInterface>
      </joint>
    </transmission>
    
  </xacro:macro>

  <xacro:wheel_front prefix="drivewhl_l" x_reflect="-1" y_reflect="1" />
  <xacro:wheel_front prefix="drivewhl_r" x_reflect="-1" y_reflect="-1" />
  
<!--############################## ARM ########################################-->
<!-- manipulator arm - first joint -->  
  <gazebo reference="first_joint">
    <material>Gazebo/White</material>
  </gazebo>
   
    <link name="first_joint">
      <visual>
        <geometry>
          <cylinder length="${0.4/scale}" radius="${cylinder_radius}"/>
        </geometry>
         <material name="White"/>
        <origin rpy="0 1.57075 0 " xyz="${-0.20/scale} ${0/scale} ${0/scale}"/>
      </visual>
      
     <!-- collision data - first joint -->               
     <collision>
       <origin rpy="0 1.57075 0 " xyz="${-0.20/scale} ${0/scale} ${0/scale}"/>
        <geometry>
          <cylinder radius="${cylinder_radius}" length="${0.4/scale}"/>
        </geometry>
     </collision>
      
     <xacro:default_inertial mass="${0.5/scale}"/>
    </link>  
    
    <joint name="first_joint_base" type="revolute">
      <axis xyz="0 1 0"/>
      <limit effort="1000.0" lower="-0.7" upper="1.35" velocity="0.5"/>
      <parent link="base_link"/>
      <child link="first_joint"/>
      <origin rpy="0 1.5708 0" xyz="${0.30/scale} ${0/scale} ${0.09/scale}"/>
    </joint>
  
  
<!-- controller - first joint -->
   <transmission name="first_joint">
     <type>transmission_interface/SimpleTransmission</type>
     <actuator name="first_joint">
       <mechanicalReduction>1</mechanicalReduction>
     </actuator>
     <joint name="first_joint_base">
	<hardwareInterface>hardware_interface/PositionJointInterface</hardwareInterface>
     </joint>
   </transmission>
  
  
<!-- manipulator arm - first joint enclosure --> 
  <gazebo reference="first_joint_enclosure">
    <material>Gazebo/White</material>
  </gazebo>
  
    <link name="first_joint_enclosure">
      <visual>
        <geometry>
          <box size="${base_length/8} ${base_width/8} ${base_height/2}"/>
        </geometry>
        <material name="White"/>
        <origin rpy="0 0 0 " xyz="${0/scale} ${0/scale} ${0/scale}"/>
      </visual>
      
<!-- collision data - first joint enclosure -->
     <collision>
      <origin rpy="0 0 0" xyz="${0/scale} ${0/scale} ${0/scale}"/>
       <geometry>
         <box size="${base_length/8} ${base_width/8} ${base_height/2}"/>
       </geometry>
     </collision>

     <xacro:default_inertial mass="${0.5/scale}"/>
    </link>
    
    <joint name="first_joint_enclosure_joint" type="fixed">
      <parent link="base_link"/>
      <child link="first_joint_enclosure"/>
      <origin rpy="0 0 0" xyz="${0.30/scale} ${0/scale} ${0.13/scale}"/>
    </joint> 
    
  
<!-- manipulator arm - second joint --> 
  <gazebo reference="second_joint">
    <material>Gazebo/White</material>
  </gazebo>
  
    <link name="second_joint">
      <visual>
        <geometry>
          <cylinder length="${0.6/scale}" radius="${cylinder_radius}"/>
        </geometry>
         <material name="White"/>
        <origin rpy="0 1.5708 0 " xyz="${0.278/scale} ${0/scale} ${0/scale}"/>
      </visual>
      
<!-- collision data - second joint -->               
     <collision>
       <origin rpy="0 1.5708 0 " xyz="${0.278/scale} ${0/scale} ${0/scale}"/>
        <geometry>
          <cylinder radius="${cylinder_radius}" length="${0.6/scale}"/>
        </geometry>
      </collision>
      
      <xacro:default_inertial mass="${0.5/scale}"/>
    </link>
    
    <joint name="second_joint_base" type="revolute">
      <axis xyz="0 1 0"/>
      <limit effort="1000.0" lower="0.0" upper="4.2" velocity="0.5"/>
      <parent link="first_joint"/>
      <child link="second_joint"/>
      <origin rpy="0 1.5708 0" xyz="${-0.4/scale} ${0/scale} ${0/scale}"/>
    </joint>


<!-- controller - second joint -->
   <transmission name="second_joint">
     <type>transmission_interface/SimpleTransmission</type>
     <actuator name="second_joint">
       <mechanicalReduction>1</mechanicalReduction>
     </actuator>
     <joint name="second_joint_base">
	<hardwareInterface>hardware_interface/PositionJointInterface</hardwareInterface>
     </joint>
   </transmission>
   

<!-- manipulator arm - second joint enclosure --> 
  <gazebo reference="second_joint_enclosure">
    <material>Gazebo/White</material>
  </gazebo>
  
    <link name="second_joint_enclosure">
      <visual>
        <geometry>
          <box size="${base_length/10} ${base_width/7} ${base_height/2}"/>
        </geometry>
         <material name="White"/>
        <origin rpy="0 0 0 " xyz="${0/scale} ${0/scale} ${0/scale}"/>
      </visual>
      
<!-- collision data - second joint enclosure -->
     <collision>
      <origin rpy="0 0 0" xyz="${0/scale} ${0/scale} ${0/scale}"/>
       <geometry>
         <box size="${base_length/10} ${base_width/7} ${base_height/2}"/>
       </geometry>
     </collision>

     <xacro:default_inertial mass="${0.5/scale}"/>
    </link>
    
    <joint name="second_joint_enclosure_joint" type="fixed">
      <parent link="first_joint"/>
      <child link="second_joint_enclosure"/>
      <origin rpy="0 0 0" xyz="${-0.4/scale} ${0/scale} ${0/scale}"/>
    </joint> 

<!-- manipulator arm - third joint --> 
  <gazebo reference="third_joint">
    <material>Gazebo/White</material>
  </gazebo>
  
    <link name="third_joint">
      <visual>
        <geometry>
          <cylinder length="${0.2/scale}" radius="${cylinder_radius}"/>
        </geometry>
         <material name="White"/>
        <origin rpy="0 1.5708 0 " xyz="${0.098/scale} ${0/scale} ${0/scale}"/>
      </visual>
      
<!-- collision data - third joint -->               
     <collision>
       <origin rpy="0 1.5708 0 " xyz="${0.098/scale} ${0/scale} ${0/scale}"/>
        <geometry>
          <cylinder radius="${cylinder_radius}" length="${0.2/scale}"/>
        </geometry>
      </collision>
      
     <xacro:default_inertial mass="${0.5/scale}"/>
    </link>
    
    <joint name="third_joint_base" type="revolute">
      <axis xyz="0 1 0"/>
      <limit effort="1000.0" lower="-1.35" upper="1.35" velocity="0.5"/>
      <parent link="second_joint"/>
      <child link="third_joint"/>
      <origin rpy="0 -1.5708 0" xyz="${0.58/scale} ${0/scale} ${0/scale}"/>
    </joint> 
    
    
<!-- controller - third joint -->
   <transmission name="third_joint">
     <type>transmission_interface/SimpleTransmission</type>
     <actuator name="third_joint">
       <mechanicalReduction>1</mechanicalReduction>
     </actuator>
     <joint name="third_joint_base">
	<hardwareInterface>hardware_interface/PositionJointInterface</hardwareInterface>
     </joint>
   </transmission>
    
    
<!-- manipulator arm - third joint enclosure --> 
  <gazebo reference="third_joint_enclosure">
    <material>Gazebo/White</material>
  </gazebo>
  
    <link name="third_joint_enclosure">
      <visual>
        <geometry>
          <box size="${base_length/6} ${base_width/6} ${base_height/2}"/>
        </geometry>
         <material name="White"/>
        <origin rpy="0 0 0 " xyz="${0/scale} ${0/scale} ${0/scale}"/>
      </visual>
      
<!-- collision data - third joint enclosure -->
      <collision>
       <origin rpy="0 0 0" xyz="${0/scale} ${0/scale} ${0/scale}"/>
        <geometry>
          <box size="${base_length/6} ${base_width/6} ${base_height/2}"/>
        </geometry>
      </collision>

     <xacro:default_inertial mass="${0.5/scale}"/>
    </link>
    
    <joint name="third_joint_enclosure_joint" type="fixed">
      <parent link="second_joint"/>
      <child link="third_joint_enclosure"/>
      <origin rpy="0 0 0" xyz="${0.58/scale} ${0/scale} ${0/scale}"/>
    </joint> 

    
<!-- manipulator arm - grabber fixture --> 
  <gazebo reference="grabber_fixture">
    <material>Gazebo/White</material>
  </gazebo>
  
    <link name="grabber_fixture">
      <visual>
        <geometry>
          <box size="${base_length/1.8} ${base_width/8} ${base_height/3}"/>
        </geometry>
         <material name="White"/>
        <origin rpy="0 0 1.5708 " xyz="${0/scale} ${0/scale} ${0/scale}"/>
      </visual>
      
<!-- collision data - grabber fixture -->
     <collision>
      <origin rpy="0 0 1.5708 " xyz="${0/scale} ${0/scale} ${0/scale}"/>
       <geometry>
         <box size="${base_length/1.8} ${base_width/8} ${base_height/3}"/>
       </geometry>
     </collision>

     <xacro:default_inertial mass="${0.5/scale}"/>
    </link>
    
    <joint name="grabber_fixture_joint" type="fixed">
      <parent link="third_joint"/>
      <child link="grabber_fixture"/>
      <origin rpy="0 0 0" xyz="${0.2/scale} ${0/scale} ${0/scale}"/>
    </joint> 
    

<!-- manipulator arm - grabber fixture left --> 
  <gazebo reference="grabber_fixture_left">
    <material>Gazebo/Grey</material>
  </gazebo>
  
    <link name="grabber_fixture_left">
      <visual>
        <geometry>
          <cylinder length="${0.3/scale}" radius="${cylinder_radius}"/>
        </geometry>
         <material name="Grey"/>
        <origin rpy="-1.5708 0 0" xyz="${0/scale} ${0.13/scale} ${0/scale}"/>
      </visual>    
      
 <!-- collision data - fixture left -->               
     <collision>
       <origin rpy="-1.5708 0 0" xyz="${0/scale} ${0.13/scale} ${0/scale}"/>
        <geometry>
          <cylinder length="${0.3/scale}" radius="${cylinder_radius}"/>
        </geometry>
      </collision>
      
     <xacro:default_inertial mass="${0.5/scale}"/>       
    </link>
    
    <joint name="grabber_fixture_left_joint" type="prismatic">
      <axis xyz="0 1 0"/>
      <limit effort="1000.0" lower="0" upper="0.20" velocity="0.5"/>
      <parent link="grabber_fixture"/>
      <child link="grabber_fixture_left"/>
      <origin rpy="0 0 0" xyz="${0/scale} ${0/scale} ${0/scale}"/>
    </joint> 

<!-- controller - fixture left -->
   <transmission name="grabber_fixture_left_trans">
     <type>transmission_interface/SimpleTransmission</type>
     <actuator name="grabber_fixture_left_motor">
       <mechanicalReduction>1</mechanicalReduction>
     </actuator>
     <joint name="grabber_fixture_left_joint">
	<hardwareInterface>hardware_interface/PositionJointInterface</hardwareInterface>
     </joint>
   </transmission>
  
  
<!-- manipulator arm - grabber fixture right --> 
  <gazebo reference="grabber_fixture_right">
    <material>Gazebo/Grey</material>
  </gazebo>
  
    <link name="grabber_fixture_right">
      <visual>
        <geometry>
          <cylinder length="${0.3/scale}" radius="${cylinder_radius}"/>
        </geometry>
         <material name="Grey"/>
        <origin rpy="1.5708 0 0" xyz="${0/scale} ${-0.13/scale} ${0/scale}"/>
      </visual>
      
 <!-- collision data - fixture right -->               
     <collision>
       <origin rpy="1.5708 0 0" xyz="${0/scale} ${-0.13/scale} ${0/scale}"/>
        <geometry>
          <cylinder length="${0.3/scale}" radius="${cylinder_radius}"/>
        </geometry>
      </collision>
      
     <xacro:default_inertial mass="${0.5/scale}"/>   
    </link>
    
    <joint name="grabber_fixture_right_joint" type="prismatic">
      <axis xyz="0 -1 0"/>
      <limit effort="1000.0" lower="0" upper="0.20" velocity="0.5"/>
      <parent link="grabber_fixture"/>
      <child link="grabber_fixture_right"/>
      <origin rpy="0 0 0" xyz="${0/scale} ${0/scale} ${0/scale}"/>
    </joint> 
    
<!-- controller - fixture right -->
   <transmission name="grabber_fixture_right_trans">
     <type>transmission_interface/SimpleTransmission</type>
     <actuator name="grabber_fixture_right_motor">
       <mechanicalReduction>1</mechanicalReduction>
     </actuator>
     <joint name="grabber_fixture_right_joint">
	<hardwareInterface>hardware_interface/PositionJointInterface</hardwareInterface>
     </joint>
   </transmission>
       
    
<!-- manipulator arm - left gripper -->   
    <joint name="left_gripper_joint" type="revolute">
      <axis xyz="0 0 1"/>
      <limit effort="1000.0" lower="-0.548" upper="0.548" velocity="0.5"/>
      <origin rpy="0 0 0" xyz="${0.02/scale} ${0.28/scale} ${0/scale}"/>
      <parent link="grabber_fixture_left"/>
      <child link="left_gripper"/>
    </joint>
  
    <link name="left_gripper">
      <visual>
        <origin rpy="0 0 0" xyz="${0/scale} ${0/scale} ${0/scale}"/>
        <geometry>
          <mesh filename="package://robot_design/meshes/l_finger.dae" scale="${0.5/scale} ${0.5/scale} ${0.5/scale}"/>
        </geometry>
      </visual>
      
<!-- collision data - left gripper -->     
      <collision>
        <geometry>
          <mesh filename="package://robot_design/meshes/l_finger.dae" scale="${0.5/scale} ${0.5/scale} ${0.5/scale}"/>
        </geometry>
         <origin rpy="0 0 0" xyz="${0/scale} ${0/scale} ${0/scale}"/>
      </collision>
      <xacro:default_inertial mass="${0.05/scale}"/>
    </link>
    
<!-- manipulator arm - left gripper controller-->   
    <transmission name="left_gripper_joint_trans">
      <type>transmission_interface/SimpleTransmission</type>
      <actuator name="left_gripper_joint_motor">
        <mechanicalReduction>1</mechanicalReduction>
      </actuator>
      <joint name="left_gripper_joint">
	<hardwareInterface>hardware_interface/PositionJointInterface</hardwareInterface>
      </joint>
    </transmission>
  
    <joint name="left_tip_joint" type="fixed">
      <parent link="left_gripper"/>
      <child link="left_tip"/>
    </joint>
  
    <link name="left_tip">
      <visual>  
        <origin rpy="0 0 0" xyz="${0.09137/scale} ${0.00495/scale} ${0/scale}"/>
        <geometry>
          <mesh filename="package://robot_design/meshes/l_finger_tip.dae" scale="${0.5/scale} ${0.5/scale} ${0.5/scale}"/>
        </geometry>
      </visual>
      
      <collision>
        <geometry>
          <mesh filename="package://robot_design/meshes/l_finger_tip.dae" scale="${0.5/scale} ${0.5/scale} ${0.5/scale}"/>
        </geometry>
         <origin rpy="0 0 0" xyz="${0.09137/scale} ${0.00495/scale} ${0/scale}"/>
      </collision>
      <xacro:default_inertial mass="${0.05/scale}"/>
    </link>
    
    
<!-- manipulator arm - right gripper -->  
    <joint name="right_gripper_joint" type="revolute">
      <axis xyz="0 0 -1"/>
      <limit effort="1000.0" lower="-0.548" upper="0.548" velocity="0.5"/>
      <origin rpy="0 0 0" xyz="${0.02/scale} ${-0.28/scale} ${0/scale}"/>
      <parent link="grabber_fixture_right"/>
      <child link="right_gripper"/>
    </joint>
  
    <link name="right_gripper">
      <visual>
        <origin rpy="-3.1415 0 0" xyz="${0/scale} ${0/scale} ${0/scale}"/>
        <geometry>
          <mesh filename="package://robot_design/meshes/l_finger.dae" scale="${0.5/scale} ${0.5/scale} ${0.5/scale}"/>
        </geometry>
      </visual>
      
<!-- collision data - right gripper -->     
      <collision>
        <geometry>
          <mesh filename="package://robot_design/meshes/l_finger.dae" scale="${0.5/scale} ${0.5/scale} ${0.5/scale}"/>
        </geometry>
         <origin rpy="-3.1415 0 0" xyz="${0/scale} ${0/scale} ${0/scale}"/>
      </collision>
      <xacro:default_inertial mass="${0.05/scale}"/>
    </link>
    
<!-- manipulator arm - right gripper controller-->   
    <transmission name="right_gripper_joint_trans">
      <type>transmission_interface/SimpleTransmission</type>
      <actuator name="right_gripper_joint_motor">
        <mechanicalReduction>1</mechanicalReduction>
      </actuator>
      <joint name="right_gripper_joint">
	<hardwareInterface>hardware_interface/PositionJointInterface</hardwareInterface>
      </joint>
    </transmission>


    <joint name="right_tip_joint" type="fixed">
      <parent link="right_gripper"/>
      <child link="right_tip"/>
    </joint>
  
    <link name="right_tip">
      <visual>
        <origin rpy="-3.1415 0 0" xyz="${0.09137/scale} ${0.00495/scale} ${0/scale}"/>
        <geometry>
          <mesh filename="package://robot_design/meshes/l_finger_tip.dae" scale="${0.5/scale} ${0.5/scale} ${0.5/scale}"/>
        </geometry>
      </visual>
      
      <collision>
        <geometry>
          <mesh filename="package://robot_design/meshes/l_finger_tip.dae" scale="${0.5/scale} ${0.5/scale} ${0.5/scale}"/>
        </geometry>
         <origin rpy="-3.1415 0 0" xyz="${0.09137/scale} ${0.00495/scale} ${0/scale}"/>
      </collision>
      <xacro:default_inertial mass="${0.05/scale}"/>
    </link>


<!--############################### SENSORS ##################################-->  
<!-- laser scanner plugin -->  
<gazebo reference="sensor_laser">
  <material>Gazebo/Cyan</material>
   <sensor type="ray" name="head_hokuyo_sensor">
      <pose>0 0 0 0 0 0</pose>
      <visualize>false</visualize>
      <update_rate>20</update_rate>
      <ray>
        <scan>
          <horizontal>
            <samples>720</samples>
            <resolution>1</resolution>
            <min_angle>0</min_angle>
            <max_angle>3.14159</max_angle>
          </horizontal>
        </scan>
        <range>
          <min>0.10</min>
          <max>15.0</max>
          <resolution>0.01</resolution>
        </range>
        <noise>
          <type>gaussian</type>
          <mean>0.0</mean>
          <stddev>0.01</stddev>
        </noise>
      </ray>
      <plugin name="gazebo_ros_head_hokuyo_controller" filename="libgazebo_ros_laser.so">
        <topicName>robot_design/laser/scan</topicName>
        <frameName>sensor_laser</frameName>
      </plugin>
    </sensor>
</gazebo>

 <!-- laser scanner link -->     
    <link name="sensor_laser">
      <visual>
        <origin xyz="${0/scale} ${0/scale} ${0/scale}" rpy="0 0 0" />
        <geometry>
          <cylinder radius="${cylinder_radius*5}" length="${0.06/scale}"/>
        </geometry>
        <material name="Cyan"/>
      </visual>

      <collision>
        <origin xyz="${0/scale} ${0/scale} ${0/scale}" rpy="0 0 0"/>
        <geometry>
          <cylinder radius="${cylinder_radius*5}" length="${0.06/scale}"/>
        </geometry>
      </collision>
      
      <xacro:default_inertial mass="${0.1/scale}"/>        
    </link>

    <joint name="joint_sensor_laser" type="fixed">
      <origin rpy="0 0 0" xyz="${0/scale} ${0/scale} ${0.12/scale}"/>
      <parent link="base_link"/>
      <child link="sensor_laser"/>
    </joint> 

 <!-- IMU scanner plugin --> 
  <gazebo reference="sensor_imu">
    <gravity>true</gravity>
    <sensor name="imu_sensor" type="imu">
      <always_on>true</always_on>
      <update_rate>100</update_rate>
      <visualize>true</visualize>
      <topic>__default_topic__</topic>
      <plugin filename="libgazebo_ros_imu_sensor.so" name="imu_plugin">
        <topicName>imu_data</topicName>
        <bodyName>sensor_imu</bodyName>
        <updateRateHZ>10.0</updateRateHZ>
        <gaussianNoise>0.0</gaussianNoise>
        <xyzOffset>0 0 0</xyzOffset>
        <rpyOffset>0 0 0</rpyOffset>
        <frameName>sensor_imu</frameName>
        <initialOrientationAsReference>false</initialOrientationAsReference>
      </plugin>
      <pose>0 0 0 0 0 0</pose>
    </sensor>
  </gazebo>
  
<!-- IMU scanner link -->  
  <link name="sensor_imu">
    <inertial>
      <mass value="${0.001/scale}"/>
      <origin rpy="0 0 0" xyz="${0/scale} ${0/scale} ${0/scale}"/>
      <inertia ixx="0.0001" ixy="0" ixz="0" iyy="0.000001" iyz="0" izz="0.0001"/>
    </inertial>
    <visual>
      <origin rpy="0 0 0" xyz="${0/scale} ${0/scale} ${0/scale}"/>
      <geometry>
        <box size="${base_length/10} ${base_width/10} ${base_height/10}"/>
      </geometry>
    </visual>
<!-- IMU scanner collision data-->     
    <collision>
      <origin rpy="0 0 0" xyz="${0/scale} ${0/scale} ${0/scale}"/>
      <geometry>
        <box size="${base_length/10} ${base_width/10} ${base_height/10}"/>
      </geometry>
    </collision>
  </link>

  <joint name="imu_joint" type="fixed">
    <axis xyz="1 0 0"/> <!-- 0 1 0 -->
      <origin xyz="${0/scale} ${0/scale} ${-0.05/scale}"/>
      <parent link="base_link"/>
      <child link="sensor_imu"/>
  </joint>


<!--############################## GAZEBO ##################################-->
<!-- gazebo control plugin -->  
  <gazebo>
    <plugin name="gazebo_ros_control" filename="libgazebo_ros_control.so">
      <robotNamespace>/</robotNamespace>
      <controlPeriod>0.001</controlPeriod>
      <legacyModeNS>false</legacyModeNS>
    </plugin>
  </gazebo>


<gazebo>
     <plugin name="joint_state_publisher" filename="libgazebo_ros_joint_state_publisher.so">
        <jointName>first_joint_base, second_joint_base, third_joint_base, grabber_fixture_left_joint, grabber_fixture_right_joint, left_gripper_joint, right_gripper_joint</jointName>
     </plugin>
</gazebo>
  
<gazebo>
<plugin name="p3d_base_controller" filename="libgazebo_ros_p3d.so">
  <alwaysOn>true</alwaysOn>
  <updateRate>50.0</updateRate>
  <bodyName>base_link</bodyName>
  <topicName>/base_truth_odom</topicName>
  <gaussianNoise>0.01</gaussianNoise>
  <frameName>world</frameName>
  <xyzOffsets>0 0 0</xyzOffsets>
  <rpyOffsets>0 0 0</rpyOffsets>
</plugin>
</gazebo>

</robot>
